<?xml version="1.0"?>
<robot name="mobile_base">

    <!-- Define base link -->
    <link name="base_link">
        <visual>
            <geometry>
                <box size="0.5 0.3 0.1"/>
            </geometry>
        </visual>
        <collision>
            <geometry>
                <box size="0.5 0.3 0.1"/>
            </geometry>
        </collision>
        <inertial>
            <mass value="1.0"/>
            <inertia ixx="0.01" ixy="0.0" ixz="0.0" iyy="0.01" iyz="0.0" izz="0.01"/>
        </inertial>
    </link>

    <!-- Define front-left wheel -->
    <link name="front_left_wheel">
        <visual>
            <geometry>
                <cylinder radius="0.05" length="0.1"/>
            </geometry>
        </visual>
        <collision>
            <geometry>
                <cylinder radius="0.05" length="0.1"/>
            </geometry>
        </collision>
        <inertial>
            <mass value="0.2"/>
            <inertia ixx="0.001" ixy="0.0" ixz="0.0" iyy="0.001" iyz="0.0" izz="0.001"/>
        </inertial>
    </link>

    <!-- Define front-right wheel -->
    <link name="front_right_wheel">
        <visual>
            <geometry>
                <cylinder radius="0.05" length="0.1"/>
            </geometry>
        </visual>
        <collision>
            <geometry>
                <cylinder radius="0.05" length="0.1"/>
            </geometry>
        </collision>
        <inertial>
            <mass value="0.2"/>
            <inertia ixx="0.001" ixy="0.0" ixz="0.0" iyy="0.001" iyz="0.0" izz="0.001"/>
        </inertial>
    </link>

    <!-- Define rear-left wheel -->
    <link name="rear_left_wheel">
        <visual>
            <geometry>
                <cylinder radius="0.05" length="0.1"/>
            </geometry>
        </visual>
        <collision>
            <geometry>
                <cylinder radius="0.05" length="0.1"/>
            </geometry>
        </collision>
        <inertial>
            <mass value="0.2"/>
            <inertia ixx="0.001" ixy="0.0" ixz="0.0" iyy="0.001" iyz="0.0" izz="0.001"/>
        </inertial>
    </link>

    <!-- Define rear-right wheel -->
    <link name="rear_right_wheel">
        <visual>
            <geometry>
                <cylinder radius="0.05" length="0.1"/>
            </geometry>
        </visual>
        <collision>
            <geometry>
                <cylinder radius="0.05" length="0.1"/>
            </geometry>
        </collision>
        <inertial>
            <mass value="0.2"/>
            <inertia ixx="0.001" ixy="0.0" ixz="0.0" iyy="0.001" iyz="0.0" izz="0.001"/>
        </inertial>
    </link>

    <!-- Define joints for wheels -->
    <joint name="front_left_wheel_joint" type="revolute">
        <parent link="base_link"/>
        <child link="front_left_wheel"/>
        <origin xyz="0.25 0.15 0.05" rpy="0 0 0"/>
        <axis xyz="0 0 1"/>
        <limit effort="50" velocity="5"/>
    </joint>

    <joint name="front_right_wheel_joint" type="revolute">
        <parent link="base_link"/>
        <child link="front_right_wheel"/>
        <origin xyz="0.25 -0.15 0.05" rpy="0 0 0"/>
        <axis xyz="0 0 1"/>
        <limit effort="50" velocity="5"/>
    </joint>

    <joint name="rear_left_wheel_joint" type="revolute">
        <parent link="base_link"/>
        <child link="rear_left_wheel"/>
        <origin xyz="-0.25 0.15 0.05" rpy="0 0 0"/>
        <axis xyz="0 0 1"/>
        <limit effort="50" velocity="5"/>
    </joint>

    <joint name="rear_right_wheel_joint" type="revolute">
        <parent link="base_link"/>
        <child link="rear_right_wheel"/>
        <origin xyz="-0.25 -0.15 0.05" rpy="0 0 0"/>
        <axis xyz="0 0 1"/>
        <limit effort="50" velocity="5"/>
    </joint>

</robot>
