<?xml version="1.0"?>
<robot xmlns:xacro="http://www.ros.org/wiki/xacro" name="mobile_base">

    <!-- Define the base link -->
    <link name="base_link">
        <visual>
            <geometry>
                <box size="0.5 0.3 0.1"/>
            </geometry>
        </visual>
        <collision>
            <geometry>
                <box size="0.5 0.3 0.1"/>
            </geometry>
        </collision>
    </link>

    <!-- Define the wheels as a macro -->
    <xacro:macro name="wheel" params="name x y">
        <link name="${name}">
            <visual>
                <geometry>
                    <cylinder radius="0.05" length="0.1"/>
                </geometry>
            </visual>
            <collision>
                <geometry>
                    <cylinder radius="0.05" length="0.1"/>
                </geometry>
            </collision>
        </link>

        <joint name="${name}_joint" type="revolute">
            <parent link="base_link"/>
            <child link="${name}"/>
            <origin xyz="${x} ${y} 0.05" rpy="0 0 0"/>
            <axis xyz="0 0 1"/>
            <limit effort="50" velocity="5"/>
        </joint>
    </xacro:macro>

    <!-- Use the wheel macro for each wheel -->
    <xacro:wheel name="front_left_wheel" x="0.25" y="0.15"/>
    <xacro:wheel name="front_right_wheel" x="0.25" y="-0.15"/>
    <xacro:wheel name="rear_left_wheel" x="-0.25" y="0.15"/>
    <xacro:wheel name="rear_right_wheel" x="-0.25" y="-0.15"/>

</robot>
